Workbook

Sheet Instrucoes
B2: MATRIZ DE LEOPOLD - AVALIACAO DE IMPACTO AMBIENTAL
B3: Planilha de apoio didatico. Preencha apenas a aba Memoria de Calculo; a matriz colorida e os totais sao recalculados automaticamente.
B5: Como a planilha funciona
B6: A matriz de Leopold cruza as acoes previstas para o empreendimento, dispostas nas linhas, com os fatores ambientais que podem ser atingidos, dispostos nas colunas. Cada cruzamento recebe uma nota que resume a magnitude e a importancia da interacao. Nesta planilha a nota nao e digitada diretamente na matriz, porque ela nasce da aba Memoria de Calculo, onde cada cruzamento e decomposto em cinco atributos julgados separadamente pelo avaliador. O valor sintetico retorna para a aba Matriz de Leopold por formula, de modo que qualquer mudanca de julgamento se propaga na hora para a cor da celula, para o total da acao e para o total do fator.
B7: A regra de calculo
B8: O carater informa se a interacao e adversa, nula ou benefica, e assume os valores -1, 0 e +1. Os outros quatro atributos sao intensidades julgadas de zero a tres e descrevem, respectivamente, quanto o fator e afetado, qual a extensao espacial atingida, por quanto tempo o efeito persiste e quao dificil e reverte-lo. A nota final do cruzamento e o produto do carater pela soma dos quatro atributos, o que confina o resultado ao intervalo de -12 a +12 e preserva o sinal do julgamento inicial. Quando o carater e zero a nota se anula por construcao, e o cruzamento passa a ser lido como ausencia de interacao relevante.
B9: Escalas adotadas
B11: Atributo | C11: 0 | D11: 1 | E11: 2 | F11: 3 | G11: Leitura
B12: Carater (Ca) | C12: nulo | D12: -1 adverso / +1 benefico | G12: sinal do impacto; zera o cruzamento quando nao ha interacao
B13: Importancia (I) | C13: nula | D13: baixa | E13: media | F13: alta | G13: quanto o fator e efetivamente alterado
B14: Cobertura (Co) | C14: nula | D14: pontual | E14: local | F14: regional | G14: extensao espacial atingida pelo efeito
B15: Duracao (D) | C15: nula | D15: curta (ate 1 ano) | E15: media (1 a 5 anos) | F15: longa (acima de 5 anos) | G15: permanencia do efeito depois da acao
B16: Reversibilidade (R) | C16: nula | D16: reversivel a curto prazo | E16: reversivel a longo prazo | F16: irreversivel | G16: capacidade de retorno a condicao anterior
B18: Convencao de cores da matriz
C19: Impacto negativo, nota menor que zero
C20: Interacao nula ou nao significativa, nota igual a zero
C21: Impacto positivo, nota maior que zero
B23: Para adaptar a planilha a outro empreendimento basta substituir os nomes das acoes e dos fatores nas duas abas, mantendo a mesma ordem, e rejulgar os cinco atributos de cada cruzamento. As linhas e colunas que nao se aplicarem podem ter o carater zerado, o que as neutraliza sem quebrar nenhuma formula.

Sheet Matriz de Leopold
A1: MATRIZ DE LEOPOLD - AVALIACAO DE IMPACTO AMBIENTAL
A2: Empreendimento: | B2: [preencher] | P2: Avaliador: | Q2: [preencher]
A4: ACOES DE PROJETO | B4: Acao / interveniencia | C4: ELEMENTOS NATURAIS E HUMANOS | T4: TOTAL da acao | U4: N. impactos negativos | V4: N. impactos positivos
C5: CARACTERISTICAS FISICAS E QUIMICAS | K5: CONDICOES BIOLOGICAS | O5: FATORES CULTURAIS / STATUS CULTURAL | R5: RELACOES ECOLOGICAS
C6: Terra | F6: Agua | I6: Atmosfera | J6: Processos | K6: Flora | M6: Fauna | O6: Uso humano | R6: Ecologia
C7: Materiais de Construcao | D7: Solos | E7: Caracteristicas Fisicas | F7: Superficial | G7: Qualidade | H7: Recarga | I7: Qualidade (gases, particulas) | J7: Erosao | K7: Arvores | L7: Arbustos | M7: Aves | N7: Animais terrestres | O7: Saude e seguranca | P7: Empregos | Q7: Densidade populacional | R7: Cadeia alimentar | S7: Usurpacao de matas
A8: Modificacoes de Regime | B8: Modificacao de Habitat | C8: ='Memoria de Calculo'!C10 -> -7 | D8: ='Memoria de Calculo'!D10 -> -9 | E8: ='Memoria de Calculo'!E10 -> -11 | F8: ='Memoria de Calculo'!F10 -> -7 | G8: ='Memoria de Calculo'!G10 -> 0 | H8: ='Memoria de Calculo'!H10 -> -4 | I8: ='Memoria de Calculo'!I10 -> 0 | J8: ='Memoria de Calculo'!J10 -> -10 | ... S8: ='Memoria de Calculo'!S10 -> -6 | T8: =SUM(C8:S8) -> -83 | U8: =COUNTIF(C8:S8,"<0") -> 12 | V8: =COUNTIF(C8:S8,">0") -> 0
B9: Alteracao da Cobertura do Solo | C9: ='Memoria de Calculo'!C16 -> -10 | D9: ='Memoria de Calculo'!D16 -> -5 | E9: ='Memoria de Calculo'!E16 -> -10 | F9: ='Memoria de Calculo'!F16 -> -8 | G9: ='Memoria de Calculo'!G16 -> 0 | H9: ='Memoria de Calculo'!H16 -> -8 | I9: ='Memoria de Calculo'!I16 -> 0 | J9: ='Memoria de Calculo'!J16 -> -10 | ... S9: ='Memoria de Calculo'!S16 -> 0 | T9: =SUM(C9:S9) -> -69 | U9: =COUNTIF(C9:S9,"<0") -> 10 | V9: =COUNTIF(C9:S9,">0") -> 0
B10: Alteracao do Balanco Hidrologico | C10: ='Memoria de Calculo'!C22 -> 0 | D10: ='Memoria de Calculo'!D22 -> 0 | E10: ='Memoria de Calculo'!E22 -> 0 | F10: ='Memoria de Calculo'!F22 -> -9 | G10: ='Memoria de Calculo'!G22 -> 0 | H10: ='Memoria de Calculo'!H22 -> -9 | I10: ='Memoria de Calculo'!I22 -> 0 | J10: ='Memoria de Calculo'!J22 -> 0 | ... S10: ='Memoria de Calculo'!S22 -> 0 | T10: =SUM(C10:S10) -> -38 | U10: =COUNTIF(C10:S10,"<0") -> 7 | V10: =COUNTIF(C10:S10,">0") -> 0
B11: Alteracao da Drenagem | C11: ='Memoria de Calculo'!C28 -> 0 | D11: ='Memoria de Calculo'!D28 -> -9 | E11: ='Memoria de Calculo'!E28 -> 0 | F11: ='Memoria de Calculo'!F28 -> -9 | G11: ='Memoria de Calculo'!G28 -> 0 | H11: ='Memoria de Calculo'!H28 -> -9 | I11: ='Memoria de Calculo'!I28 -> 0 | J11: ='Memoria de Calculo'!J28 -> -8 | ... S11: ='Memoria de Calculo'!S28 -> 0 | T11: =SUM(C11:S11) -> -47 | U11: =COUNTIF(C11:S11,"<0") -> 6 | V11: =COUNTIF(C11:S11,">0") -> 0
B12: Pavimentacao de Superficies | C12: ='Memoria de Calculo'!C34 -> 0 | D12: ='Memoria de Calculo'!D34 -> -10 | E12: ='Memoria de Calculo'!E34 -> 0 | F12: ='Memoria de Calculo'!F34 -> -10 | G12: ='Memoria de Calculo'!G34 -> 0 | H12: ='Memoria de Calculo'!H34 -> -10 | I12: ='Memoria de Calculo'!I34 -> 0 | J12: ='Memoria de Calculo'!J34 -> -8 | ... S12: ='Memoria de Calculo'!S34 -> 0 | T12: =SUM(C12:S12) -> -45 | U12: =COUNTIF(C12:S12,"<0") -> 7 | V12: =COUNTIF(C12:S12,">0") -> 1
B13: Ruidos ou Vibracao | C13: ='Memoria de Calculo'!C40 -> 0 | D13: ='Memoria de Calculo'!D40 -> 0 | E13: ='Memoria de Calculo'!E40 -> 0 | F13: ='Memoria de Calculo'!F40 -> 0 | G13: ='Memoria de Calculo'!G40 -> 0 | H13: ='Memoria de Calculo'!H40 -> 0 | I13: ='Memoria de Calculo'!I40 -> 0 | J13: ='Memoria de Calculo'!J40 -> 0 | ... S13: ='Memoria de Calculo'!S40 -> 0 | T13: =SUM(C13:S13) -> -13 | U13: =COUNTIF(C13:S13,"<0") -> 3 | V13: =COUNTIF(C13:S13,">0") -> 0
A14: Transformacao do Espaco e Construcao | B14: Aterro | C14: ='Memoria de Calculo'!C46 -> 0 | D14: ='Memoria de Calculo'!D46 -> 0 | E14: ='Memoria de Calculo'!E46 -> -5 | F14: ='Memoria de Calculo'!F46 -> -5 | G14: ='Memoria de Calculo'!G46 -> 0 | H14: ='Memoria de Calculo'!H46 -> -10 | I14: ='Memoria de Calculo'!I46 -> 0 | J14: ='Memoria de Calculo'!J46 -> 6 | ... S14: ='Memoria de Calculo'!S46 -> 0 | T14: =SUM(C14:S14) -> -17 | U14: =COUNTIF(C14:S14,"<0") -> 5 | V14: =COUNTIF(C14:S14,">0") -> 2
B15: Escavacoes de Superficie | C15: ='Memoria de Calculo'!C52 -> 0 | D15: ='Memoria de Calculo'!D52 -> -5 | E15: ='Memoria de Calculo'!E52 -> -9 | F15: ='Memoria de Calculo'!F52 -> -7 | G15: ='Memoria de Calculo'!G52 -> 0 | H15: ='Memoria de Calculo'!H52 -> -5 | I15: ='Memoria de Calculo'!I52 -> 0 | J15: ='Memoria de Calculo'!J52 -> -9 | ... S15: ='Memoria de Calculo'!S52 -> -4 | T15: =SUM(C15:S15) -> -53 | U15: =COUNTIF(C15:S15,"<0") -> 10 | V15: =COUNTIF(C15:S15,">0") -> 1
A16: TOTAL do fator | C16: =SUM(C8:C15) -> -17 | D16: =SUM(D8:D15) -> -38 | E16: =SUM(E8:E15) -> -35 | F16: =SUM(F8:F15) -> -55 | G16: =SUM(G8:G15) -> 0 | H16: =SUM(H8:H15) -> -55 | I16: =SUM(I8:I15) -> 0 | J16: =SUM(J8:J15) -> -39 | ... T16: =SUM(T8:T15) -> -365
A17: N. impactos negativos | C17: =COUNTIF(C8:C15,"<0") -> 2 | D17: =COUNTIF(D8:D15,"<0") -> 5 | E17: =COUNTIF(E8:E15,"<0") -> 4 | F17: =COUNTIF(F8:F15,"<0") -> 7 | G17: =COUNTIF(G8:G15,"<0") -> 0 | H17: =COUNTIF(H8:H15,"<0") -> 7 | I17: =COUNTIF(I8:I15,"<0") -> 0 | J17: =COUNTIF(J8:J15,"<0") -> 5 | ... S17: =COUNTIF(S8:S15,"<0") -> 2
A18: N. impactos positivos | C18: =COUNTIF(C8:C15,">0") -> 0 | D18: =COUNTIF(D8:D15,">0") -> 0 | E18: =COUNTIF(E8:E15,">0") -> 0 | F18: =COUNTIF(F8:F15,">0") -> 0 | G18: =COUNTIF(G8:G15,">0") -> 0 | H18: =COUNTIF(H8:H15,">0") -> 0 | I18: =COUNTIF(I8:I15,">0") -> 0 | J18: =COUNTIF(J8:J15,">0") -> 1 | ... S18: =COUNTIF(S8:S15,">0") -> 0
B20: Legenda
B21: Negativo
B22: Neutro, sem interacao
B23: Positivo
B25: Nota de cada cruzamento igual a Ca x (I + Co + D + R), com Ca em -1, 0 ou +1 e os demais atributos de 0 a 3, o que limita a nota ao intervalo de -12 a +12. Os valores vem da aba Memoria de Calculo.

Sheet Memoria de Calculo
A1: MEMORIA DE CALCULO - JULGAMENTO DOS ATRIBUTOS POR CRUZAMENTO
A2: Edite somente as linhas Ca, I, Co, D e R. A linha TOTAL e calculada e alimenta a aba Matriz de Leopold. Ca aceita -1, 0 ou +1; os demais atributos aceitam 0, 1, 2 ou 3.
A4: Acao do projeto | B4: Atributo | C4: Materiais de Construcao | D4: Solos | E4: Caracteristicas Fisicas | F4: Superficial | G4: Qualidade | H4: Recarga | I4: Qualidade (gases, particulas) | J4: Erosao | K4: Arvores | L4: Arbustos | M4: Aves | N4: Animais terrestres | O4: Saude e seguranca | P4: Empregos | Q4: Densidade populacional | R4: Cadeia alimentar | S4: Usurpacao de matas
A5: Modificacao de Habitat | B5: Carater (Ca) | C5: -1 | D5: -1 | E5: -1 | F5: -1 | G5: 0 | H5: -1 | I5: 0 | J5: -1 | K5: -1 | L5: -1 | M5: -1 | N5: -1 | O5: 0 | P5: 0 | Q5: 0 | R5: -1 | S5: -1
B6: Importancia (I) | C6: 2 | D6: 2 | E6: 3 | F6: 2 | G6: 0 | H6: 1 | I6: 0 | J6: 3 | K6: 1 | L6: 3 | M6: 1 | N6: 2 | O6: 0 | P6: 0 | Q6: 0 | R6: 2 | S6: 2
B7: Cobertura (Co) | C7: 2 | D7: 2 | E7: 2 | F7: 1 | G7: 0 | H7: 1 | I7: 0 | J7: 2 | K7: 1 | L7: 1 | M7: 1 | N7: 1 | O7: 0 | P7: 0 | Q7: 0 | R7: 2 | S7: 2
B8: Duracao (D) | C8: 2 | D8: 3 | E8: 3 | F8: 2 | G8: 0 | H8: 1 | I8: 0 | J8: 3 | K8: 1 | L8: 1 | M8: 3 | N8: 1 | O8: 0 | P8: 0 | Q8: 0 | R8: 1 | S8: 1
B9: Reversibilidade (R) | C9: 1 | D9: 2 | E9: 3 | F9: 2 | G9: 0 | H9: 1 | I9: 0 | J9: 2 | K9: 1 | L9: 1 | M9: 3 | N9: 1 | O9: 0 | P9: 0 | Q9: 0 | R9: 1 | S9: 1
B10: TOTAL = Ca x (I+Co+D+R) | C10: =C5*(C6+C7+C8+C9) -> -7 | D10: =D5*(D6+D7+D8+D9) -> -9 | E10: =E5*(E6+E7+E8+E9) -> -11 | F10: =F5*(F6+F7+F8+F9) -> -7 | G10: =G5*(G6+G7+G8+G9) -> 0 | H10: =H5*(H6+H7+H8+H9) -> -4 | I10: =I5*(I6+I7+I8+I9) -> 0 | J10: =J5*(J6+J7+J8+J9) -> -10 | ... S10: =S5*(S6+S7+S8+S9) -> -6
A11: Alteracao da Cobertura do Solo | B11: Carater (Ca) | C11: -1 | D11: -1 | E11: -1 | F11: -1 | G11: 0 | H11: -1 | I11: 0 | J11: -1 | K11: -1 | L11: -1 | M11: -1 | N11: -1 | O11: 0 | P11: 0 | Q11: 0 | R11: 0 | S11: 0
B12: Importancia (I) | C12: 2 | D12: 1 | E12: 2 | F12: 2 | G12: 0 | H12: 2 | I12: 0 | J12: 3 | K12: 2 | L12: 2 | M12: 1 | N12: 1 | O12: 0 | P12: 0 | Q12: 0 | R12: 0 | S12: 0
B13: Cobertura (Co) | C13: 2 | D13: 1 | E13: 2 | F13: 1 | G13: 0 | H13: 2 | I13: 0 | J13: 2 | K13: 1 | L13: 1 | M13: 1 | N13: 1 | O13: 0 | P13: 0 | Q13: 0 | R13: 0 | S13: 0
B14: Duracao (D) | C14: 3 | D14: 1 | E14: 3 | F14: 3 | G14: 0 | H14: 2 | I14: 0 | J14: 3 | K14: 1 | L14: 1 | M14: 1 | N14: 1 | O14: 0 | P14: 0 | Q14: 0 | R14: 0 | S14: 0
B15: Reversibilidade (R) | C15: 3 | D15: 2 | E15: 3 | F15: 2 | G15: 0 | H15: 2 | I15: 0 | J15: 2 | K15: 1 | L15: 1 | M15: 1 | N15: 1 | O15: 0 | P15: 0 | Q15: 0 | R15: 0 | S15: 0
B16: TOTAL = Ca x (I+Co+D+R) | C16: =C11*(C12+C13+C14+C15) -> -10 | D16: =D11*(D12+D13+D14+D15) -> -5 | E16: =E11*(E12+E13+E14+E15) -> -10 | F16: =F11*(F12+F13+F14+F15) -> -8 | G16: =G11*(G12+G13+G14+G15) -> 0 | H16: =H11*(H12+H13+H14+H15) -> -8 | I16: =I11*(I12+I13+I14+I15) -> 0 | J16: =J11*(J12+J13+J14+J15) -> -10 | ... S16: =S11*(S12+S13+S14+S15) -> 0
A17: Alteracao do Balanco Hidrologico | B17: Carater (Ca) | C17: 0 | D17: 0 | E17: 0 | F17: -1 | G17: 0 | H17: -1 | I17: 0 | J17: 0 | K17: -1 | L17: -1 | M17: -1 | N17: -1 | O17: 0 | P17: 0 | Q17: 0 | R17: -1 | S17: 0
B18: Importancia (I) | C18: 0 | D18: 0 | E18: 0 | F18: 3 | G18: 0 | H18: 3 | I18: 0 | J18: 0 | K18: 1 | L18: 1 | M18: 1 | N18: 1 | O18: 0 | P18: 0 | Q18: 0 | R18: 1 | S18: 0
B19: Cobertura (Co) | C19: 0 | D19: 0 | E19: 0 | F19: 2 | G19: 0 | H19: 2 | I19: 0 | J19: 0 | K19: 1 | L19: 1 | M19: 1 | N19: 1 | O19: 0 | P19: 0 | Q19: 0 | R19: 1 | S19: 0
B20: Duracao (D) | C20: 0 | D20: 0 | E20: 0 | F20: 2 | G20: 0 | H20: 2 | I20: 0 | J20: 0 | K20: 1 | L20: 1 | M20: 1 | N20: 1 | O20: 0 | P20: 0 | Q20: 0 | R20: 1 | S20: 0
B21: Reversibilidade (R) | C21: 0 | D21: 0 | E21: 0 | F21: 2 | G21: 0 | H21: 2 | I21: 0 | J21: 0 | K21: 1 | L21: 1 | M21: 1 | N21: 1 | O21: 0 | P21: 0 | Q21: 0 | R21: 1 | S21: 0
B22: TOTAL = Ca x (I+Co+D+R) | C22: =C17*(C18+C19+C20+C21) -> 0 | D22: =D17*(D18+D19+D20+D21) -> 0 | E22: =E17*(E18+E19+E20+E21) -> 0 | F22: =F17*(F18+F19+F20+F21) -> -9 | G22: =G17*(G18+G19+G20+G21) -> 0 | H22: =H17*(H18+H19+H20+H21) -> -9 | I22: =I17*(I18+I19+I20+I21) -> 0 | J22: =J17*(J18+J19+J20+J21) -> 0 | ... S22: =S17*(S18+S19+S20+S21) -> 0
A23: Alteracao da Drenagem | B23: Carater (Ca) | C23: 0 | D23: -1 | E23: 0 | F23: -1 | G23: 0 | H23: -1 | I23: 0 | J23: -1 | K23: -1 | L23: -1 | M23: 0 | N23: 0 | O23: 0 | P23: 0 | Q23: 0 | R23: 0 | S23: 0
B24: Importancia (I) | C24: 0 | D24: 2 | E24: 0 | F24: 3 | G24: 0 | H24: 3 | I24: 0 | J24: 3 | K24: 2 | L24: 2 | M24: 0 | N24: 0 | O24: 0 | P24: 0 | Q24: 0 | R24: 0 | S24: 0
B25: Cobertura (Co) | C25: 0 | D25: 2 | E25: 0 | F25: 2 | G25: 0 | H25: 2 | I25: 0 | J25: 2 | K25: 2 | L25: 2 | M25: 0 | N25: 0 | O25: 0 | P25: 0 | Q25: 0 | R25: 0 | S25: 0
B26: Duracao (D) | C26: 0 | D26: 3 | E26: 0 | F26: 2 | G26: 0 | H26: 2 | I26: 0 | J26: 2 | K26: 1 | L26: 1 | M26: 0 | N26: 0 | O26: 0 | P26: 0 | Q26: 0 | R26: 0 | S26: 0
B27: Reversibilidade (R) | C27: 0 | D27: 2 | E27: 0 | F27: 2 | G27: 0 | H27: 2 | I27: 0 | J27: 1 | K27: 1 | L27: 1 | M27: 0 | N27: 0 | O27: 0 | P27: 0 | Q27: 0 | R27: 0 | S27: 0
B28: TOTAL = Ca x (I+Co+D+R) | C28: =C23*(C24+C25+C26+C27) -> 0 | D28: =D23*(D24+D25+D26+D27) -> -9 | E28: =E23*(E24+E25+E26+E27) -> 0 | F28: =F23*(F24+F25+F26+F27) -> -9 | G28: =G23*(G24+G25+G26+G27) -> 0 | H28: =H23*(H24+H25+H26+H27) -> -9 | I28: =I23*(I24+I25+I26+I27) -> 0 | J28: =J23*(J24+J25+J26+J27) -> -8 | ... S28: =S23*(S24+S25+S26+S27) -> 0
A29: Pavimentacao de Superficies | B29: Carater (Ca) | C29: 0 | D29: -1 | E29: 0 | F29: -1 | G29: 0 | H29: -1 | I29: 0 | J29: -1 | K29: -1 | L29: -1 | M29: 0 | N29: -1 | O29: 0 | P29: 1 | Q29: 0 | R29: 0 | S29: 0
B30: Importancia (I) | C30: 0 | D30: 3 | E30: 0 | F30: 3 | G30: 0 | H30: 3 | I30: 0 | J30: 2 | K30: 1 | L30: 1 | M30: 0 | N30: 1 | O30: 0 | P30: 2 | Q30: 0 | R30: 0 | S30: 0
B31: Cobertura (Co) | C31: 0 | D31: 2 | E31: 0 | F31: 2 | G31: 0 | H31: 2 | I31: 0 | J31: 2 | K31: 1 | L31: 1 | M31: 0 | N31: 1 | O31: 0 | P31: 1 | Q31: 0 | R31: 0 | S31: 0
B32: Duracao (D) | C32: 0 | D32: 3 | E32: 0 | F32: 3 | G32: 0 | H32: 3 | I32: 0 | J32: 2 | K32: 1 | L32: 1 | M32: 0 | N32: 1 | O32: 0 | P32: 1 | Q32: 0 | R32: 0 | S32: 0
B33: Reversibilidade (R) | C33: 0 | D33: 2 | E33: 0 | F33: 2 | G33: 0 | H33: 2 | I33: 0 | J33: 2 | K33: 1 | L33: 1 | M33: 0 | N33: 1 | O33: 0 | P33: 1 | Q33: 0 | R33: 0 | S33: 0
B34: TOTAL = Ca x (I+Co+D+R) | C34: =C29*(C30+C31+C32+C33) -> 0 | D34: =D29*(D30+D31+D32+D33) -> -10 | E34: =E29*(E30+E31+E32+E33) -> 0 | F34: =F29*(F30+F31+F32+F33) -> -10 | G34: =G29*(G30+G31+G32+G33) -> 0 | H34: =H29*(H30+H31+H32+H33) -> -10 | I34: =I29*(I30+I31+I32+I33) -> 0 | J34: =J29*(J30+J31+J32+J33) -> -8 | ... S34: =S29*(S30+S31+S32+S33) -> 0
A35: Ruidos ou Vibracao | B35: Carater (Ca) | C35: 0 | D35: 0 | E35: 0 | F35: 0 | G35: 0 | H35: 0 | I35: 0 | J35: 0 | K35: 0 | L35: 0 | M35: -1 | N35: -1 | O35: -1 | P35: 0 | Q35: 0 | R35: 0 | S35: 0
B36: Importancia (I) | C36: 0 | D36: 0 | E36: 0 | F36: 0 | G36: 0 | H36: 0 | I36: 0 | J36: 0 | K36: 0 | L36: 0 | M36: 1 | N36: 2 | O36: 1 | P36: 0 | Q36: 0 | R36: 0 | S36: 0
B37: Cobertura (Co) | C37: 0 | D37: 0 | E37: 0 | F37: 0 | G37: 0 | H37: 0 | I37: 0 | J37: 0 | K37: 0 | L37: 0 | M37: 1 | N37: 1 | O37: 1 | P37: 0 | Q37: 0 | R37: 0 | S37: 0
B38: Duracao (D) | C38: 0 | D38: 0 | E38: 0 | F38: 0 | G38: 0 | H38: 0 | I38: 0 | J38: 0 | K38: 0 | L38: 0 | M38: 1 | N38: 1 | O38: 1 | P38: 0 | Q38: 0 | R38: 0 | S38: 0
B39: Reversibilidade (R) | C39: 0 | D39: 0 | E39: 0 | F39: 0 | G39: 0 | H39: 0 | I39: 0 | J39: 0 | K39: 0 | L39: 0 | M39: 1 | N39: 1 | O39: 1 | P39: 0 | Q39: 0 | R39: 0 | S39: 0
B40: TOTAL = Ca x (I+Co+D+R) | C40: =C35*(C36+C37+C38+C39) -> 0 | D40: =D35*(D36+D37+D38+D39) -> 0 | E40: =E35*(E36+E37+E38+E39) -> 0 | F40: =F35*(F36+F37+F38+F39) -> 0 | G40: =G35*(G36+G37+G38+G39) -> 0 | H40: =H35*(H36+H37+H38+H39) -> 0 | I40: =I35*(I36+I37+I38+I39) -> 0 | J40: =J35*(J36+J37+J38+J39) -> 0 | ... S40: =S35*(S36+S37+S38+S39) -> 0
A41: Aterro | B41: Carater (Ca) | C41: 0 | D41: 0 | E41: -1 | F41: -1 | G41: 0 | H41: -1 | I41: 0 | J41: 1 | K41: 0 | L41: 0 | M41: 0 | N41: -1 | O41: 0 | P41: 1 | Q41: 0 | R41: -1 | S41: 0
...

Sheet Sintese
B2: SINTESE - HIERARQUIZACAO DE ACOES E FATORES
B3: Os valores desta aba sao lidos da matriz. Quanto mais negativo o somatorio, maior a contribuicao da acao para a degradacao esperada, ou maior a sensibilidade do fator ao conjunto do empreendimento. Ordene as tabelas pela coluna Somatorio para obter a hierarquia.
B5: Acoes do projeto
B6: Acao | C6: Somatorio | D6: Negativos | E6: Positivos | F6: Media por fator
B7: ='Matriz de Leopold'!B8 -> Modificacao de Habitat | C7: ='Matriz de Leopold'!T8 -> -83 | D7: ='Matriz de Leopold'!U8 -> 12 | E7: ='Matriz de Leopold'!V8 -> 0 | F7: =ROUND(C7/17,2) -> -4.88
B8: ='Matriz de Leopold'!B9 -> Alteracao da Cobertura do Solo | C8: ='Matriz de Leopold'!T9 -> -69 | D8: ='Matriz de Leopold'!U9 -> 10 | E8: ='Matriz de Leopold'!V9 -> 0 | F8: =ROUND(C8/17,2) -> -4.06
B9: ='Matriz de Leopold'!B10 -> Alteracao do Balanco Hidrologico | C9: ='Matriz de Leopold'!T10 -> -38 | D9: ='Matriz de Leopold'!U10 -> 7 | E9: ='Matriz de Leopold'!V10 -> 0 | F9: =ROUND(C9/17,2) -> -2.24
B10: ='Matriz de Leopold'!B11 -> Alteracao da Drenagem | C10: ='Matriz de Leopold'!T11 -> -47 | D10: ='Matriz de Leopold'!U11 -> 6 | E10: ='Matriz de Leopold'!V11 -> 0 | F10: =ROUND(C10/17,2) -> -2.76
B11: ='Matriz de Leopold'!B12 -> Pavimentacao de Superficies | C11: ='Matriz de Leopold'!T12 -> -45 | D11: ='Matriz de Leopold'!U12 -> 7 | E11: ='Matriz de Leopold'!V12 -> 1 | F11: =ROUND(C11/17,2) -> -2.65
B12: ='Matriz de Leopold'!B13 -> Ruidos ou Vibracao | C12: ='Matriz de Leopold'!T13 -> -13 | D12: ='Matriz de Leopold'!U13 -> 3 | E12: ='Matriz de Leopold'!V13 -> 0 | F12: =ROUND(C12/17,2) -> -0.76
B13: ='Matriz de Leopold'!B14 -> Aterro | C13: ='Matriz de Leopold'!T14 -> -17 | D13: ='Matriz de Leopold'!U14 -> 5 | E13: ='Matriz de Leopold'!V14 -> 2 | F13: =ROUND(C13/17,2) -> -1
B14: ='Matriz de Leopold'!B15 -> Escavacoes de Superficie | C14: ='Matriz de Leopold'!T15 -> -53 | D14: ='Matriz de Leopold'!U15 -> 10 | E14: ='Matriz de Leopold'!V15 -> 1 | F14: =ROUND(C14/17,2) -> -3.12
B17: Fatores ambientais
B18: Fator | C18: Somatorio | D18: Negativos | E18: Positivos | F18: Media por acao
B19: Materiais de Construcao | C19: ='Matriz de Leopold'!C16 -> -17 | D19: ='Matriz de Leopold'!C17 -> 2 | E19: ='Matriz de Leopold'!C18 -> 0 | F19: =ROUND(C19/8,2) -> -2.13
B20: Solos | C20: ='Matriz de Leopold'!D16 -> -38 | D20: ='Matriz de Leopold'!D17 -> 5 | E20: ='Matriz de Leopold'!D18 -> 0 | F20: =ROUND(C20/8,2) -> -4.75
B21: Caracteristicas Fisicas | C21: ='Matriz de Leopold'!E16 -> -35 | D21: ='Matriz de Leopold'!E17 -> 4 | E21: ='Matriz de Leopold'!E18 -> 0 | F21: =ROUND(C21/8,2) -> -4.38
B22: Superficial | C22: ='Matriz de Leopold'!F16 -> -55 | D22: ='Matriz de Leopold'!F17 -> 7 | E22: ='Matriz de Leopold'!F18 -> 0 | F22: =ROUND(C22/8,2) -> -6.88
B23: Qualidade | C23: ='Matriz de Leopold'!G16 -> 0 | D23: ='Matriz de Leopold'!G17 -> 0 | E23: ='Matriz de Leopold'!G18 -> 0 | F23: =ROUND(C23/8,2) -> 0
B24: Recarga | C24: ='Matriz de Leopold'!H16 -> -55 | D24: ='Matriz de Leopold'!H17 -> 7 | E24: ='Matriz de Leopold'!H18 -> 0 | F24: =ROUND(C24/8,2) -> -6.88
B25: Qualidade (gases, particulas) | C25: ='Matriz de Leopold'!I16 -> 0 | D25: ='Matriz de Leopold'!I17 -> 0 | E25: ='Matriz de Leopold'!I18 -> 0 | F25: =ROUND(C25/8,2) -> 0
B26: Erosao | C26: ='Matriz de Leopold'!J16 -> -39 | D26: ='Matriz de Leopold'!J17 -> 5 | E26: ='Matriz de Leopold'!J18 -> 1 | F26: =ROUND(C26/8,2) -> -4.88
B27: Arvores | C27: ='Matriz de Leopold'!K16 -> -28 | D27: ='Matriz de Leopold'!K17 -> 6 | E27: ='Matriz de Leopold'!K18 -> 0 | F27: =ROUND(C27/8,2) -> -3.5
B28: Arbustos | C28: ='Matriz de Leopold'!L16 -> -31 | D28: ='Matriz de Leopold'!L17 -> 6 | E28: ='Matriz de Leopold'!L18 -> 0 | F28: =ROUND(C28/8,2) -> -3.88
B29: Aves | C29: ='Matriz de Leopold'!M16 -> -20 | D29: ='Matriz de Leopold'!M17 -> 4 | E29: ='Matriz de Leopold'!M18 -> 0 | F29: =ROUND(C29/8,2) -> -2.5
B30: Animais terrestres | C30: ='Matriz de Leopold'!N16 -> -30 | D30: ='Matriz de Leopold'!N17 -> 7 | E30: ='Matriz de Leopold'!N18 -> 0 | F30: =ROUND(C30/8,2) -> -3.75
B31: Saude e seguranca | C31: ='Matriz de Leopold'!O16 -> -4 | D31: ='Matriz de Leopold'!O17 -> 1 | E31: ='Matriz de Leopold'!O18 -> 0 | F31: =ROUND(C31/8,2) -> -0.5
B32: Empregos | C32: ='Matriz de Leopold'!P16 -> 15 | D32: ='Matriz de Leopold'!P17 -> 0 | E32: ='Matriz de Leopold'!P18 -> 3 | F32: =ROUND(C32/8,2) -> 1.88
B33: Densidade populacional | C33: ='Matriz de Leopold'!Q16 -> 0 | D33: ='Matriz de Leopold'!Q17 -> 0 | E33: ='Matriz de Leopold'!Q18 -> 0 | F33: =ROUND(C33/8,2) -> 0
B34: Cadeia alimentar | C34: ='Matriz de Leopold'!R16 -> -18 | D34: ='Matriz de Leopold'!R17 -> 4 | E34: ='Matriz de Leopold'!R18 -> 0 | F34: =ROUND(C34/8,2) -> -2.25
B35: Usurpacao de matas | C35: ='Matriz de Leopold'!S16 -> -10 | D35: ='Matriz de Leopold'!S17 -> 2 | E35: ='Matriz de Leopold'!S18 -> 0 | F35: =ROUND(C35/8,2) -> -1.25
B38: Balanco liquido do empreendimento | D38: ='Matriz de Leopold'!T16 -> -365
